<?xml version="1.0" ?>
<!-- =================================================================================== -->
<!-- |    This document was autogenerated by xacro from antmodel.xacro                 | -->
<!-- |    EDITING THIS FILE BY HAND IS NOT RECOMMENDED                                 | -->
<!-- =================================================================================== -->
<!-- Synthesis of an Ant Leg -->
<robot name="antmodel" xmlns:xacro="http://www.ros.org/wiki/xacro">
  <!-- Link 3 -->
  <!-- norm(link{1,2}(10,:)) -->
  <!-- tr2rpy(A{50})(3) -->
  <!-- length of tibia + tarsus segment  <origin xyz="${baseX} ${baseY} ${baseZ}"/> -->
  <!-- Body mass -->
  <!-- ros_control plugin -->
  <gazebo>
    <plugin filename="libgazebo_ros_control.so" name="gazebo_ros_control">
      <robotNamespace>/antmodel</robotNamespace>
      <robotSimType>gazebo_ros_control/DefaultRobotHWSim</robotSimType>
    </plugin>
  </gazebo>
  <material name="black">
    <color rgba="0.0 0.0 0.0 1.0"/>
  </material>
  <material name="blue">
    <color rgba="0.0 0.0 0.8 1.0"/>
  </material>
  <material name="green">
    <color rgba="0.0 0.8 0.0 1.0"/>
  </material>
  <material name="grey">
    <color rgba="0.2 0.2 0.2 1.0"/>
  </material>
  <material name="orange">
    <color rgba="1.0 0.423529411765 0.0392156862745 1.0"/>
  </material>
  <material name="brown">
    <color rgba="0.870588235294 0.811764705882 0.764705882353 1.0"/>
  </material>
  <material name="red">
    <color rgba="0.8 0.0 0.0 1.0"/>
  </material>
  <material name="white">
    <color rgba="1.0 1.0 1.0 1.0"/>
  </material>
  <!-- to fix body-->
  <link name="world"/>
  <joint name="world_joint" type="fixed">
    <origin rpy="0 0 0" xyz="0 0 2.00635"/>
    <parent link="world"/>
    <child link="body"/>
  </joint>
  <link name="body">
    <visual>
      <origin rpy="0 0 0" xyz="0 0 2.00635"/>
      <geometry>
        <box size="4 0.7 0.7"/>
      </geometry>
    </visual>
    <!--
<collision>
      <origin xyz="0 0 ${AZ/2}" rpy="0 0 0"/>
      <geometry>
	<box size="${body_length} ${body_width} ${body_height}"/>
      </geometry>
    </collision>
-->
    <collision>
      <origin rpy="0 0 0" xyz="0 0 2.00635"/>
      <geometry>
        <box size="0 0 0"/>
      </geometry>
    </collision>
    <inertial>
      <origin rpy="0 0 0" xyz="0 0 0"/>
      <mass value="0.97559947"/>
      <inertia ixx="3.1081800" ixy="-0.25460189" ixz="2.0318174" iyy="6.3787776" iyz="0.16417863" izz="5.3316425"/>
    </inertial>
  </link>
  <gazebo reference="body">
    <material>Gazebo/White</material>
  </gazebo>
  <!-- Base -->
  <link name="base_lf">
    <collision>
      <origin rpy="0 0 0" xyz="0 0 -2.00635"/>
      <geometry>
        <box size="0.1 0.1 5"/>
      </geometry>
    </collision>
    <visual>
      <origin rpy="0 0 0" xyz="1.316 0 0"/>
      <geometry>
        <box size="2.632 0.1 0.1"/>
      </geometry>
      <material name="orange"/>
    </visual>
    <inertial>
      <origin rpy="0 0 0" xyz="0 0 2.5"/>
      <mass value="0.024357719"/>
      <inertia ixx="0.0507655460158" ixy="0.0" ixz="0.0" iyy="0.0507655460158" iyz="0.0" izz="4.05961983333e-05"/>
    </inertial>
  </link>
  <!-- Coxa Link -->
  <link name="coxa_lf">
    <collision>
      <origin rpy="0 0 0" xyz="0 0 0"/>
      <geometry>
        <box size="0.1 0.1 0.1"/>
      </geometry>
    </collision>
    <visual>
      <origin rpy="0 0 0" xyz="0 0 0"/>
      <geometry>
        <box size="0.1 0.1 0.1"/>
      </geometry>
      <material name="black"/>
    </visual>
    <inertial>
      <origin rpy="0 0 0" xyz="0 0 0"/>
      <mass value="0.024357719"/>
      <inertia ixx="0.0051411124" ixy="-0.00057530255" ixz="-0.000024729049" iyy="0.0081915737" iyz="-0.000019223094" izz="0.0011379812"/>
    </inertial>
  </link>
  <!-- Link DOF1 -->
  <link name="link1_lf">
    <collision>
      <origin rpy="0 0 0" xyz="0 0 0"/>
      <geometry>
        <box size="0.1 0.1 0.1"/>
      </geometry>
    </collision>
    <visual>
      <origin rpy="0 0 0" xyz="0 0 0"/>
      <geometry>
        <box size="0.1 0.1 0.1"/>
      </geometry>
      <material name="black"/>
    </visual>
    <inertial>
      <origin rpy="0 0 0" xyz="0 0 0"/>
      <mass value="0.024357719"/>
      <inertia ixx="0.0051411124" ixy="-0.00057530255" ixz="-0.000024729049" iyy="0.0081915737" iyz="-0.000019223094" izz="0.0011379812"/>
    </inertial>
  </link>
  <!-- Link DOF2 -->
  <link name="link2_lf">
    <collision>
      <origin rpy="0 0 0" xyz="0 0 0"/>
      <geometry>
        <box size="0.1 0.1 0.1"/>
      </geometry>
    </collision>
    <visual>
      <origin rpy="0 0 0" xyz="0 0 0"/>
      <geometry>
        <box size="0.1 0.1 0.1"/>
      </geometry>
      <material name="orange"/>
    </visual>
    <inertial>
      <origin rpy="0 0 0" xyz="0 0 0"/>
      <mass value="0.024357719"/>
      <inertia ixx="0.0051411124" ixy="-0.00057530255" ixz="-0.000024729049" iyy="0.0081915737" iyz="-0.000019223094" izz="0.0011379812"/>
    </inertial>
  </link>
  <!-- Femur Link -->
  <link name="femur_lf">
    <collision>
      <origin rpy="0 1.57079632679 0" xyz="0.85 0 0"/>
      <geometry>
        <cylinder length="1.7" radius="0.05"/>
      </geometry>
    </collision>
    <visual>
      <origin rpy="0 1.57079632679 0" xyz="0.85 0 0"/>
      <geometry>
        <cylinder length="1.7" radius="0.05"/>
      </geometry>
      <material name="orange"/>
    </visual>
    <inertial>
      <origin rpy="0 0 0" xyz="0.85 0 0"/>
      <mass value="0.024357719"/>
      <inertia ixx="0.0051411124" ixy="-0.00057530255" ixz="-0.000024729049" iyy="0.0081915737" iyz="-0.000019223094" izz="0.0011379812"/>
    </inertial>
  </link>
  <!-- Tibia Link -->
  <link name="tibia_lf">
    <collision>
      <origin rpy="0 1.57079632679 0" xyz="1.3 0 0"/>
      <geometry>
        <cylinder length="2.6" radius="0.02"/>
      </geometry>
    </collision>
    <visual>
      <origin rpy="0 1.57079632679 0" xyz="1.3 0 0"/>
      <geometry>
        <cylinder length="2.6" radius="0.02"/>
      </geometry>
      <material name="orange"/>
    </visual>
    <inertial>
      <origin rpy="0 0 0" xyz="1.3 0 0"/>
      <mass value="0.024357719"/>
      <inertia ixx="0.0051411124" ixy="-0.00057530255" ixz="-0.000024729049" iyy="0.0081915737" iyz="-0.000019223094" izz="0.0011379812"/>
    </inertial>
    <mu1>1</mu1>
    <mu2>1</mu2>
  </link>
  <joint name="j_body_lf" type="fixed">
    <parent link="body"/>
    <child link="base_lf"/>
    <origin rpy="-0.9202 0.1936 0.1716" xyz="2.0 0.35 2.00635"/>
  </joint>
  <!-- Frame {A} -->
  <joint name="A" type="fixed">
    <parent link="base_lf"/>
    <child link="coxa_lf"/>
    <origin xyz="2.632 0 0"/>
  </joint>
  <!-- DOF1 = q1 -->
  <joint name="joint1_lf" type="continuous">
    <parent link="coxa_lf"/>
    <child link="link1_lf"/>
    <origin rpy="0 0 0" xyz="0 0 0"/>
    <axis xyz="0 0 1"/>
    <dynamics damping="0.7"/>
  </joint>
  <!-- DOF2 = q2 -->
  <joint name="joint2_lf" type="continuous">
    <parent link="link1_lf"/>
    <child link="link2_lf"/>
    <origin rpy="-1.57079632679 0 0" xyz="0 0 0"/>
    <axis xyz="0 0 1"/>
    <dynamics damping="0.7"/>
  </joint>
  <!-- DOF3 = q3 -->
  <joint name="joint3_lf" type="continuous">
    <parent link="link2_lf"/>
    <child link="femur_lf"/>
    <origin rpy="1.57079632679 0 0" xyz="0 0 0"/>
    <axis xyz="0 0 1"/>
    <dynamics damping="0.7"/>
  </joint>
  <!-- DOF4 = q4 -->
  <joint name="joint4_lf" type="continuous">
    <parent link="femur_lf"/>
    <child link="tibia_lf"/>
    <origin rpy="0 0 0" xyz="1.7 0 0"/>
    <axis xyz="0 0 1"/>
    <dynamics damping="0.7"/>
  </joint>
  <gazebo reference="coxa_lf">
    <material>Gazebo/Blue</material>
  </gazebo>
  <gazebo reference="femur_lf">
    <material>Gazebo/Green</material>
  </gazebo>
  <gazebo reference="link1_lf">
    <material>Gazebo/Orange</material>
  </gazebo>
  <gazebo reference="link2_lf">
    <material>Gazebo/Red</material>
  </gazebo>
  <!-- Transmission to ROS -->
  <transmission name="tran1_lf">
    <type>transmission_interface/SimpleTransmission</type>
    <joint name="joint1_lf">
      <hardwareInterface>EffortJointInterface</hardwareInterface>
    </joint>
    <actuator name="motor1_lf">
      <hardwareInterface>EffortJointInterface</hardwareInterface>
      <mechanicalReduction>1</mechanicalReduction>
    </actuator>
  </transmission>
  <transmission name="tran2_lf">
    <type>transmission_interface/SimpleTransmission</type>
    <joint name="joint2_lf">
      <hardwareInterface>EffortJointInterface</hardwareInterface>
    </joint>
    <actuator name="motor2_lf">
      <hardwareInterface>EffortJointInterface</hardwareInterface>
      <mechanicalReduction>1</mechanicalReduction>
    </actuator>
  </transmission>
  <transmission name="tran3_lf">
    <type>transmission_interface/SimpleTransmission</type>
    <joint name="joint3_lf">
      <hardwareInterface>EffortJointInterface</hardwareInterface>
    </joint>
    <actuator name="motor3_lf">
      <hardwareInterface>EffortJointInterface</hardwareInterface>
      <mechanicalReduction>1</mechanicalReduction>
    </actuator>
  </transmission>
  <transmission name="tran4_lf">
    <type>transmission_interface/SimpleTransmission</type>
    <joint name="joint4_lf">
      <hardwareInterface>EffortJointInterface</hardwareInterface>
    </joint>
    <actuator name="motor4_lf">
      <hardwareInterface>EffortJointInterface</hardwareInterface>
      <mechanicalReduction>1</mechanicalReduction>
    </actuator>
  </transmission>
  <!-- Base -->
  <link name="base_lm">
    <collision>
      <origin rpy="0 0 0" xyz="0 0 -2.00635"/>
      <geometry>
        <box size="0.1 0.1 5"/>
      </geometry>
    </collision>
    <visual>
      <origin rpy="0 0 0" xyz="1.316 0 0"/>
      <geometry>
        <box size="2.632 0.1 0.1"/>
      </geometry>
      <material name="orange"/>
    </visual>
    <inertial>
      <origin rpy="0 0 0" xyz="0 0 2.5"/>
      <mass value="0.024357719"/>
      <inertia ixx="0.0507655460158" ixy="0.0" ixz="0.0" iyy="0.0507655460158" iyz="0.0" izz="4.05961983333e-05"/>
    </inertial>
  </link>
  <!-- Coxa Link -->
  <link name="coxa_lm">
    <collision>
      <origin rpy="0 0 0" xyz="0 0 0"/>
      <geometry>
        <box size="0.1 0.1 0.1"/>
      </geometry>
    </collision>
    <visual>
      <origin rpy="0 0 0" xyz="0 0 0"/>
      <geometry>
        <box size="0.1 0.1 0.1"/>
      </geometry>
      <material name="black"/>
    </visual>
    <inertial>
      <origin rpy="0 0 0" xyz="0 0 0"/>
      <mass value="0.024357719"/>
      <inertia ixx="0.0051411124" ixy="-0.00057530255" ixz="-0.000024729049" iyy="0.0081915737" iyz="-0.000019223094" izz="0.0011379812"/>
    </inertial>
  </link>
  <!-- Link DOF1 -->
  <link name="link1_lm">
    <collision>
      <origin rpy="0 0 0" xyz="0 0 0"/>
      <geometry>
        <box size="0.1 0.1 0.1"/>
      </geometry>
    </collision>
    <visual>
      <origin rpy="0 0 0" xyz="0 0 0"/>
      <geometry>
        <box size="0.1 0.1 0.1"/>
      </geometry>
      <material name="black"/>
    </visual>
    <inertial>
      <origin rpy="0 0 0" xyz="0 0 0"/>
      <mass value="0.024357719"/>
      <inertia ixx="0.0051411124" ixy="-0.00057530255" ixz="-0.000024729049" iyy="0.0081915737" iyz="-0.000019223094" izz="0.0011379812"/>
    </inertial>
  </link>
  <!-- Link DOF2 -->
  <link name="link2_lm">
    <collision>
      <origin rpy="0 0 0" xyz="0 0 0"/>
      <geometry>
        <box size="0.1 0.1 0.1"/>
      </geometry>
    </collision>
    <visual>
      <origin rpy="0 0 0" xyz="0 0 0"/>
      <geometry>
        <box size="0.1 0.1 0.1"/>
      </geometry>
      <material name="orange"/>
    </visual>
    <inertial>
      <origin rpy="0 0 0" xyz="0 0 0"/>
      <mass value="0.024357719"/>
      <inertia ixx="0.0051411124" ixy="-0.00057530255" ixz="-0.000024729049" iyy="0.0081915737" iyz="-0.000019223094" izz="0.0011379812"/>
    </inertial>
  </link>
  <!-- Femur Link -->
  <link name="femur_lm">
    <collision>
      <origin rpy="0 1.57079632679 0" xyz="0.85 0 0"/>
      <geometry>
        <cylinder length="1.7" radius="0.05"/>
      </geometry>
    </collision>
    <visual>
      <origin rpy="0 1.57079632679 0" xyz="0.85 0 0"/>
      <geometry>
        <cylinder length="1.7" radius="0.05"/>
      </geometry>
      <material name="orange"/>
    </visual>
    <inertial>
      <origin rpy="0 0 0" xyz="0.85 0 0"/>
      <mass value="0.024357719"/>
      <inertia ixx="0.0051411124" ixy="-0.00057530255" ixz="-0.000024729049" iyy="0.0081915737" iyz="-0.000019223094" izz="0.0011379812"/>
    </inertial>
  </link>
  <!-- Tibia Link -->
  <link name="tibia_lm">
    <collision>
      <origin rpy="0 1.57079632679 0" xyz="1.3 0 0"/>
      <geometry>
        <cylinder length="2.6" radius="0.02"/>
      </geometry>
    </collision>
    <visual>
      <origin rpy="0 1.57079632679 0" xyz="1.3 0 0"/>
      <geometry>
        <cylinder length="2.6" radius="0.02"/>
      </geometry>
      <material name="orange"/>
    </visual>
    <inertial>
      <origin rpy="0 0 0" xyz="1.3 0 0"/>
      <mass value="0.024357719"/>
      <inertia ixx="0.0051411124" ixy="-0.00057530255" ixz="-0.000024729049" iyy="0.0081915737" iyz="-0.000019223094" izz="0.0011379812"/>
    </inertial>
    <mu1>1</mu1>
    <mu2>1</mu2>
  </link>
  <joint name="j_body_lm" type="fixed">
    <parent link="body"/>
    <child link="base_lm"/>
    <origin rpy="-0.9202 0.1936 0.5" xyz="0 0.35 2.00635"/>
  </joint>
  <!-- Frame {A} -->
  <joint name="A" type="fixed">
    <parent link="base_lm"/>
    <child link="coxa_lm"/>
    <origin xyz="2.632 0 0"/>
  </joint>
  <!-- DOF1 = q1 -->
  <joint name="joint1_lm" type="continuous">
    <parent link="coxa_lm"/>
    <child link="link1_lm"/>
    <origin rpy="0 0 0" xyz="0 0 0"/>
    <axis xyz="0 0 1"/>
    <dynamics damping="0.7"/>
  </joint>
  <!-- DOF2 = q2 -->
  <joint name="joint2_lm" type="continuous">
    <parent link="link1_lm"/>
    <child link="link2_lm"/>
    <origin rpy="-1.57079632679 0 0" xyz="0 0 0"/>
    <axis xyz="0 0 1"/>
    <dynamics damping="0.7"/>
  </joint>
  <!-- DOF3 = q3 -->
  <joint name="joint3_lm" type="continuous">
    <parent link="link2_lm"/>
    <child link="femur_lm"/>
    <origin rpy="1.57079632679 0 0" xyz="0 0 0"/>
    <axis xyz="0 0 1"/>
    <dynamics damping="0.7"/>
  </joint>
  <!-- DOF4 = q4 -->
  <joint name="joint4_lm" type="continuous">
    <parent link="femur_lm"/>
    <child link="tibia_lm"/>
    <origin rpy="0 0 0" xyz="1.7 0 0"/>
    <axis xyz="0 0 1"/>
    <dynamics damping="0.7"/>
  </joint>
  <gazebo reference="coxa_lm">
    <material>Gazebo/Blue</material>
  </gazebo>
  <gazebo reference="femur_lm">
    <material>Gazebo/Green</material>
  </gazebo>
  <gazebo reference="link1_lm">
    <material>Gazebo/Orange</material>
  </gazebo>
  <gazebo reference="link2_lm">
    <material>Gazebo/Red</material>
  </gazebo>
  <!-- Transmission to ROS -->
  <transmission name="tran1_lm">
    <type>transmission_interface/SimpleTransmission</type>
    <joint name="joint1_lm">
      <hardwareInterface>EffortJointInterface</hardwareInterface>
    </joint>
    <actuator name="motor1_lm">
      <hardwareInterface>EffortJointInterface</hardwareInterface>
      <mechanicalReduction>1</mechanicalReduction>
    </actuator>
  </transmission>
  <transmission name="tran2_lm">
    <type>transmission_interface/SimpleTransmission</type>
    <joint name="joint2_lm">
      <hardwareInterface>EffortJointInterface</hardwareInterface>
    </joint>
    <actuator name="motor2_lm">
      <hardwareInterface>EffortJointInterface</hardwareInterface>
      <mechanicalReduction>1</mechanicalReduction>
    </actuator>
  </transmission>
  <transmission name="tran3_lm">
    <type>transmission_interface/SimpleTransmission</type>
    <joint name="joint3_lm">
      <hardwareInterface>EffortJointInterface</hardwareInterface>
    </joint>
    <actuator name="motor3_lm">
      <hardwareInterface>EffortJointInterface</hardwareInterface>
      <mechanicalReduction>1</mechanicalReduction>
    </actuator>
  </transmission>
  <transmission name="tran4_lm">
    <type>transmission_interface/SimpleTransmission</type>
    <joint name="joint4_lm">
      <hardwareInterface>EffortJointInterface</hardwareInterface>
    </joint>
    <actuator name="motor4_lm">
      <hardwareInterface>EffortJointInterface</hardwareInterface>
      <mechanicalReduction>1</mechanicalReduction>
    </actuator>
  </transmission>
  <!-- Base -->
  <link name="base_lr">
    <collision>
      <origin rpy="0 0 0" xyz="0 0 -2.00635"/>
      <geometry>
        <box size="0.1 0.1 5"/>
      </geometry>
    </collision>
    <visual>
      <origin rpy="0 0 0" xyz="1.316 0 0"/>
      <geometry>
        <box size="2.632 0.1 0.1"/>
      </geometry>
      <material name="orange"/>
    </visual>
    <inertial>
      <origin rpy="0 0 0" xyz="0 0 2.5"/>
      <mass value="0.024357719"/>
      <inertia ixx="0.0507655460158" ixy="0.0" ixz="0.0" iyy="0.0507655460158" iyz="0.0" izz="4.05961983333e-05"/>
    </inertial>
  </link>
  <!-- Coxa Link -->
  <link name="coxa_lr">
    <collision>
      <origin rpy="0 0 0" xyz="0 0 0"/>
      <geometry>
        <box size="0.1 0.1 0.1"/>
      </geometry>
    </collision>
    <visual>
      <origin rpy="0 0 0" xyz="0 0 0"/>
      <geometry>
        <box size="0.1 0.1 0.1"/>
      </geometry>
      <material name="black"/>
    </visual>
    <inertial>
      <origin rpy="0 0 0" xyz="0 0 0"/>
      <mass value="0.024357719"/>
      <inertia ixx="0.0051411124" ixy="-0.00057530255" ixz="-0.000024729049" iyy="0.0081915737" iyz="-0.000019223094" izz="0.0011379812"/>
    </inertial>
  </link>
  <!-- Link DOF1 -->
  <link name="link1_lr">
    <collision>
      <origin rpy="0 0 0" xyz="0 0 0"/>
      <geometry>
        <box size="0.1 0.1 0.1"/>
      </geometry>
    </collision>
    <visual>
      <origin rpy="0 0 0" xyz="0 0 0"/>
      <geometry>
        <box size="0.1 0.1 0.1"/>
      </geometry>
      <material name="black"/>
    </visual>
    <inertial>
      <origin rpy="0 0 0" xyz="0 0 0"/>
      <mass value="0.024357719"/>
      <inertia ixx="0.0051411124" ixy="-0.00057530255" ixz="-0.000024729049" iyy="0.0081915737" iyz="-0.000019223094" izz="0.0011379812"/>
    </inertial>
  </link>
  <!-- Link DOF2 -->
  <link name="link2_lr">
    <collision>
      <origin rpy="0 0 0" xyz="0 0 0"/>
      <geometry>
        <box size="0.1 0.1 0.1"/>
      </geometry>
    </collision>
    <visual>
      <origin rpy="0 0 0" xyz="0 0 0"/>
      <geometry>
        <box size="0.1 0.1 0.1"/>
      </geometry>
      <material name="orange"/>
    </visual>
    <inertial>
      <origin rpy="0 0 0" xyz="0 0 0"/>
      <mass value="0.024357719"/>
      <inertia ixx="0.0051411124" ixy="-0.00057530255" ixz="-0.000024729049" iyy="0.0081915737" iyz="-0.000019223094" izz="0.0011379812"/>
    </inertial>
  </link>
  <!-- Femur Link -->
  <link name="femur_lr">
    <collision>
      <origin rpy="0 1.57079632679 0" xyz="0.85 0 0"/>
      <geometry>
        <cylinder length="1.7" radius="0.05"/>
      </geometry>
    </collision>
    <visual>
      <origin rpy="0 1.57079632679 0" xyz="0.85 0 0"/>
      <geometry>
        <cylinder length="1.7" radius="0.05"/>
      </geometry>
      <material name="orange"/>
    </visual>
    <inertial>
      <origin rpy="0 0 0" xyz="0.85 0 0"/>
      <mass value="0.024357719"/>
      <inertia ixx="0.0051411124" ixy="-0.00057530255" ixz="-0.000024729049" iyy="0.0081915737" iyz="-0.000019223094" izz="0.0011379812"/>
    </inertial>
  </link>
  <!-- Tibia Link -->
  <link name="tibia_lr">
    <collision>
      <origin rpy="0 1.57079632679 0" xyz="1.3 0 0"/>
      <geometry>
        <cylinder length="2.6" radius="0.02"/>
      </geometry>
    </collision>
    <visual>
      <origin rpy="0 1.57079632679 0" xyz="1.3 0 0"/>
      <geometry>
        <cylinder length="2.6" radius="0.02"/>
      </geometry>
      <material name="orange"/>
    </visual>
    <inertial>
      <origin rpy="0 0 0" xyz="1.3 0 0"/>
      <mass value="0.024357719"/>
      <inertia ixx="0.0051411124" ixy="-0.00057530255" ixz="-0.000024729049" iyy="0.0081915737" iyz="-0.000019223094" izz="0.0011379812"/>
    </inertial>
    <mu1>1</mu1>
    <mu2>1</mu2>
  </link>
  <joint name="j_body_lr" type="fixed">
    <parent link="body"/>
    <child link="base_lr"/>
    <origin rpy="2.5218 -0.1517 -1.6559" xyz="-2.0 0.35 2.00635"/>
  </joint>
  <!-- Frame {A} -->
  <joint name="A" type="fixed">
    <parent link="base_lr"/>
    <child link="coxa_lr"/>
    <origin xyz="2.632 0 0"/>
  </joint>
  <!-- DOF1 = q1 -->
  <joint name="joint1_lr" type="continuous">
    <parent link="coxa_lr"/>
    <child link="link1_lr"/>
    <origin rpy="0 0 0" xyz="0 0 0"/>
    <axis xyz="0 0 1"/>
    <dynamics damping="0.7"/>
  </joint>
  <!-- DOF2 = q2 -->
  <joint name="joint2_lr" type="continuous">
    <parent link="link1_lr"/>
    <child link="link2_lr"/>
    <origin rpy="-1.57079632679 0 0" xyz="0 0 0"/>
    <axis xyz="0 0 1"/>
    <dynamics damping="0.7"/>
  </joint>
  <!-- DOF3 = q3 -->
  <joint name="joint3_lr" type="continuous">
    <parent link="link2_lr"/>
    <child link="femur_lr"/>
    <origin rpy="1.57079632679 0 0" xyz="0 0 0"/>
    <axis xyz="0 0 1"/>
    <dynamics damping="0.7"/>
  </joint>
  <!-- DOF4 = q4 -->
  <joint name="joint4_lr" type="continuous">
    <parent link="femur_lr"/>
    <child link="tibia_lr"/>
    <origin rpy="0 0 0" xyz="1.7 0 0"/>
    <axis xyz="0 0 1"/>
    <dynamics damping="0.7"/>
  </joint>
  <gazebo reference="coxa_lr">
    <material>Gazebo/Blue</material>
  </gazebo>
  <gazebo reference="femur_lr">
    <material>Gazebo/Green</material>
  </gazebo>
  <gazebo reference="link1_lr">
    <material>Gazebo/Orange</material>
  </gazebo>
  <gazebo reference="link2_lr">
    <material>Gazebo/Red</material>
  </gazebo>
  <!-- Transmission to ROS -->
  <transmission name="tran1_lr">
    <type>transmission_interface/SimpleTransmission</type>
    <joint name="joint1_lr">
      <hardwareInterface>EffortJointInterface</hardwareInterface>
    </joint>
    <actuator name="motor1_lr">
      <hardwareInterface>EffortJointInterface</hardwareInterface>
      <mechanicalReduction>1</mechanicalReduction>
    </actuator>
  </transmission>
  <transmission name="tran2_lr">
    <type>transmission_interface/SimpleTransmission</type>
    <joint name="joint2_lr">
      <hardwareInterface>EffortJointInterface</hardwareInterface>
    </joint>
    <actuator name="motor2_lr">
      <hardwareInterface>EffortJointInterface</hardwareInterface>
      <mechanicalReduction>1</mechanicalReduction>
    </actuator>
  </transmission>
  <transmission name="tran3_lr">
    <type>transmission_interface/SimpleTransmission</type>
    <joint name="joint3_lr">
      <hardwareInterface>EffortJointInterface</hardwareInterface>
    </joint>
    <actuator name="motor3_lr">
      <hardwareInterface>EffortJointInterface</hardwareInterface>
      <mechanicalReduction>1</mechanicalReduction>
    </actuator>
  </transmission>
  <transmission name="tran4_lr">
    <type>transmission_interface/SimpleTransmission</type>
    <joint name="joint4_lr">
      <hardwareInterface>EffortJointInterface</hardwareInterface>
    </joint>
    <actuator name="motor4_lr">
      <hardwareInterface>EffortJointInterface</hardwareInterface>
      <mechanicalReduction>1</mechanicalReduction>
    </actuator>
  </transmission>
  <!-- Base -->
  <link name="base_rf">
    <collision>
      <origin rpy="0 0 0" xyz="0 0 -2.00635"/>
      <geometry>
        <box size="0.1 0.1 5"/>
      </geometry>
    </collision>
    <visual>
      <origin rpy="0 0 0" xyz="1.316 0 0"/>
      <geometry>
        <box size="2.632 0.1 0.1"/>
      </geometry>
      <material name="orange"/>
    </visual>
    <inertial>
      <origin rpy="0 0 0" xyz="0 0 2.5"/>
      <mass value="0.024357719"/>
      <inertia ixx="0.0507655460158" ixy="0.0" ixz="0.0" iyy="0.0507655460158" iyz="0.0" izz="4.05961983333e-05"/>
    </inertial>
  </link>
  <!-- Coxa Link -->
  <link name="coxa_rf">
    <collision>
      <origin rpy="0 0 0" xyz="0 0 0"/>
      <geometry>
        <box size="0.1 0.1 0.1"/>
      </geometry>
    </collision>
    <visual>
      <origin rpy="0 0 0" xyz="0 0 0"/>
      <geometry>
        <box size="0.1 0.1 0.1"/>
      </geometry>
      <material name="black"/>
    </visual>
    <inertial>
      <origin rpy="0 0 0" xyz="0 0 0"/>
      <mass value="0.024357719"/>
      <inertia ixx="0.0051411124" ixy="-0.00057530255" ixz="-0.000024729049" iyy="0.0081915737" iyz="-0.000019223094" izz="0.0011379812"/>
    </inertial>
  </link>
  <!-- Link DOF1 -->
  <link name="link1_rf">
    <collision>
      <origin rpy="0 0 0" xyz="0 0 0"/>
      <geometry>
        <box size="0.1 0.1 0.1"/>
      </geometry>
    </collision>
    <visual>
      <origin rpy="0 0 0" xyz="0 0 0"/>
      <geometry>
        <box size="0.1 0.1 0.1"/>
      </geometry>
      <material name="black"/>
    </visual>
    <inertial>
      <origin rpy="0 0 0" xyz="0 0 0"/>
      <mass value="0.024357719"/>
      <inertia ixx="0.0051411124" ixy="-0.00057530255" ixz="-0.000024729049" iyy="0.0081915737" iyz="-0.000019223094" izz="0.0011379812"/>
    </inertial>
  </link>
  <!-- Link DOF2 -->
  <link name="link2_rf">
    <collision>
      <origin rpy="0 0 0" xyz="0 0 0"/>
      <geometry>
        <box size="0.1 0.1 0.1"/>
      </geometry>
    </collision>
    <visual>
      <origin rpy="0 0 0" xyz="0 0 0"/>
      <geometry>
        <box size="0.1 0.1 0.1"/>
      </geometry>
      <material name="orange"/>
    </visual>
    <inertial>
      <origin rpy="0 0 0" xyz="0 0 0"/>
      <mass value="0.024357719"/>
      <inertia ixx="0.0051411124" ixy="-0.00057530255" ixz="-0.000024729049" iyy="0.0081915737" iyz="-0.000019223094" izz="0.0011379812"/>
    </inertial>
  </link>
  <!-- Femur Link -->
  <link name="femur_rf">
    <collision>
      <origin rpy="0 1.57079632679 0" xyz="0.85 0 0"/>
      <geometry>
        <cylinder length="1.7" radius="0.05"/>
      </geometry>
    </collision>
    <visual>
      <origin rpy="0 1.57079632679 0" xyz="0.85 0 0"/>
      <geometry>
        <cylinder length="1.7" radius="0.05"/>
      </geometry>
      <material name="orange"/>
    </visual>
    <inertial>
      <origin rpy="0 0 0" xyz="0.85 0 0"/>
      <mass value="0.024357719"/>
      <inertia ixx="0.0051411124" ixy="-0.00057530255" ixz="-0.000024729049" iyy="0.0081915737" iyz="-0.000019223094" izz="0.0011379812"/>
    </inertial>
  </link>
  <!-- Tibia Link -->
  <link name="tibia_rf">
    <collision>
      <origin rpy="0 1.57079632679 0" xyz="1.3 0 0"/>
      <geometry>
        <cylinder length="2.6" radius="0.02"/>
      </geometry>
    </collision>
    <visual>
      <origin rpy="0 1.57079632679 0" xyz="1.3 0 0"/>
      <geometry>
        <cylinder length="2.6" radius="0.02"/>
      </geometry>
      <material name="orange"/>
    </visual>
    <inertial>
      <origin rpy="0 0 0" xyz="1.3 0 0"/>
      <mass value="0.024357719"/>
      <inertia ixx="0.0051411124" ixy="-0.00057530255" ixz="-0.000024729049" iyy="0.0081915737" iyz="-0.000019223094" izz="0.0011379812"/>
    </inertial>
    <mu1>1</mu1>
    <mu2>1</mu2>
  </link>
  <joint name="j_body_rf" type="fixed">
    <parent link="body"/>
    <child link="base_rf"/>
    <origin rpy="4.06179265359 0.1936 -0.1716" xyz="2.0 -0.35 2.00635"/>
  </joint>
  <!-- Frame {A} -->
  <joint name="A" type="fixed">
    <parent link="base_rf"/>
    <child link="coxa_rf"/>
    <origin xyz="2.632 0 0"/>
  </joint>
  <!-- DOF1 = q1 -->
  <joint name="joint1_rf" type="continuous">
    <parent link="coxa_rf"/>
    <child link="link1_rf"/>
    <origin rpy="0 0 0" xyz="0 0 0"/>
    <axis xyz="0 0 1"/>
    <dynamics damping="0.7"/>
  </joint>
  <!-- DOF2 = q2 -->
  <joint name="joint2_rf" type="continuous">
    <parent link="link1_rf"/>
    <child link="link2_rf"/>
    <origin rpy="-1.57079632679 0 0" xyz="0 0 0"/>
    <axis xyz="0 0 1"/>
    <dynamics damping="0.7"/>
  </joint>
  <!-- DOF3 = q3 -->
  <joint name="joint3_rf" type="continuous">
    <parent link="link2_rf"/>
    <child link="femur_rf"/>
    <origin rpy="1.57079632679 0 0" xyz="0 0 0"/>
    <axis xyz="0 0 1"/>
    <dynamics damping="0.7"/>
  </joint>
  <!-- DOF4 = q4 -->
  <joint name="joint4_rf" type="continuous">
    <parent link="femur_rf"/>
    <child link="tibia_rf"/>
    <origin rpy="0 0 0" xyz="1.7 0 0"/>
    <axis xyz="0 0 1"/>
    <dynamics damping="0.7"/>
  </joint>
  <gazebo reference="coxa_rf">
    <material>Gazebo/Blue</material>
  </gazebo>
  <gazebo reference="femur_rf">
    <material>Gazebo/Green</material>
  </gazebo>
  <gazebo reference="link1_rf">
    <material>Gazebo/Orange</material>
  </gazebo>
  <gazebo reference="link2_rf">
    <material>Gazebo/Red</material>
  </gazebo>
  <!-- Transmission to ROS -->
  <transmission name="tran1_rf">
    <type>transmission_interface/SimpleTransmission</type>
    <joint name="joint1_rf">
      <hardwareInterface>EffortJointInterface</hardwareInterface>
    </joint>
    <actuator name="motor1_rf">
      <hardwareInterface>EffortJointInterface</hardwareInterface>
      <mechanicalReduction>1</mechanicalReduction>
    </actuator>
  </transmission>
  <transmission name="tran2_rf">
    <type>transmission_interface/SimpleTransmission</type>
    <joint name="joint2_rf">
      <hardwareInterface>EffortJointInterface</hardwareInterface>
    </joint>
    <actuator name="motor2_rf">
      <hardwareInterface>EffortJointInterface</hardwareInterface>
      <mechanicalReduction>1</mechanicalReduction>
    </actuator>
  </transmission>
  <transmission name="tran3_rf">
    <type>transmission_interface/SimpleTransmission</type>
    <joint name="joint3_rf">
      <hardwareInterface>EffortJointInterface</hardwareInterface>
    </joint>
    <actuator name="motor3_rf">
      <hardwareInterface>EffortJointInterface</hardwareInterface>
      <mechanicalReduction>1</mechanicalReduction>
    </actuator>
  </transmission>
  <transmission name="tran4_rf">
    <type>transmission_interface/SimpleTransmission</type>
    <joint name="joint4_rf">
      <hardwareInterface>EffortJointInterface</hardwareInterface>
    </joint>
    <actuator name="motor4_rf">
      <hardwareInterface>EffortJointInterface</hardwareInterface>
      <mechanicalReduction>1</mechanicalReduction>
    </actuator>
  </transmission>
  <!-- Base -->
  <link name="base_rm">
    <collision>
      <origin rpy="0 0 0" xyz="0 0 -2.00635"/>
      <geometry>
        <box size="0.1 0.1 5"/>
      </geometry>
    </collision>
    <visual>
      <origin rpy="0 0 0" xyz="1.316 0 0"/>
      <geometry>
        <box size="2.632 0.1 0.1"/>
      </geometry>
      <material name="orange"/>
    </visual>
    <inertial>
      <origin rpy="0 0 0" xyz="0 0 2.5"/>
      <mass value="0.024357719"/>
      <inertia ixx="0.0507655460158" ixy="0.0" ixz="0.0" iyy="0.0507655460158" iyz="0.0" izz="4.05961983333e-05"/>
    </inertial>
  </link>
  <!-- Coxa Link -->
  <link name="coxa_rm">
    <collision>
      <origin rpy="0 0 0" xyz="0 0 0"/>
      <geometry>
        <box size="0.1 0.1 0.1"/>
      </geometry>
    </collision>
    <visual>
      <origin rpy="0 0 0" xyz="0 0 0"/>
      <geometry>
        <box size="0.1 0.1 0.1"/>
      </geometry>
      <material name="black"/>
    </visual>
    <inertial>
      <origin rpy="0 0 0" xyz="0 0 0"/>
      <mass value="0.024357719"/>
      <inertia ixx="0.0051411124" ixy="-0.00057530255" ixz="-0.000024729049" iyy="0.0081915737" iyz="-0.000019223094" izz="0.0011379812"/>
    </inertial>
  </link>
  <!-- Link DOF1 -->
  <link name="link1_rm">
    <collision>
      <origin rpy="0 0 0" xyz="0 0 0"/>
      <geometry>
        <box size="0.1 0.1 0.1"/>
      </geometry>
    </collision>
    <visual>
      <origin rpy="0 0 0" xyz="0 0 0"/>
      <geometry>
        <box size="0.1 0.1 0.1"/>
      </geometry>
      <material name="black"/>
    </visual>
    <inertial>
      <origin rpy="0 0 0" xyz="0 0 0"/>
      <mass value="0.024357719"/>
      <inertia ixx="0.0051411124" ixy="-0.00057530255" ixz="-0.000024729049" iyy="0.0081915737" iyz="-0.000019223094" izz="0.0011379812"/>
    </inertial>
  </link>
  <!-- Link DOF2 -->
  <link name="link2_rm">
    <collision>
      <origin rpy="0 0 0" xyz="0 0 0"/>
      <geometry>
        <box size="0.1 0.1 0.1"/>
      </geometry>
    </collision>
    <visual>
      <origin rpy="0 0 0" xyz="0 0 0"/>
      <geometry>
        <box size="0.1 0.1 0.1"/>
      </geometry>
      <material name="orange"/>
    </visual>
    <inertial>
      <origin rpy="0 0 0" xyz="0 0 0"/>
      <mass value="0.024357719"/>
      <inertia ixx="0.0051411124" ixy="-0.00057530255" ixz="-0.000024729049" iyy="0.0081915737" iyz="-0.000019223094" izz="0.0011379812"/>
    </inertial>
  </link>
  <!-- Femur Link -->
  <link name="femur_rm">
    <collision>
      <origin rpy="0 1.57079632679 0" xyz="0.85 0 0"/>
      <geometry>
        <cylinder length="1.7" radius="0.05"/>
      </geometry>
    </collision>
    <visual>
      <origin rpy="0 1.57079632679 0" xyz="0.85 0 0"/>
      <geometry>
        <cylinder length="1.7" radius="0.05"/>
      </geometry>
      <material name="orange"/>
    </visual>
    <inertial>
      <origin rpy="0 0 0" xyz="0.85 0 0"/>
      <mass value="0.024357719"/>
      <inertia ixx="0.0051411124" ixy="-0.00057530255" ixz="-0.000024729049" iyy="0.0081915737" iyz="-0.000019223094" izz="0.0011379812"/>
    </inertial>
  </link>
  <!-- Tibia Link -->
  <link name="tibia_rm">
    <collision>
      <origin rpy="0 1.57079632679 0" xyz="1.3 0 0"/>
      <geometry>
        <cylinder length="2.6" radius="0.02"/>
      </geometry>
    </collision>
    <visual>
      <origin rpy="0 1.57079632679 0" xyz="1.3 0 0"/>
      <geometry>
        <cylinder length="2.6" radius="0.02"/>
      </geometry>
      <material name="orange"/>
    </visual>
    <inertial>
      <origin rpy="0 0 0" xyz="1.3 0 0"/>
      <mass value="0.024357719"/>
      <inertia ixx="0.0051411124" ixy="-0.00057530255" ixz="-0.000024729049" iyy="0.0081915737" iyz="-0.000019223094" izz="0.0011379812"/>
    </inertial>
    <mu1>1</mu1>
    <mu2>1</mu2>
  </link>
  <joint name="j_body_rm" type="fixed">
    <parent link="body"/>
    <child link="base_rm"/>
    <origin rpy="4.06179265359 0.1936 -0.5" xyz="0 -0.35 2.00635"/>
  </joint>
  <!-- Frame {A} -->
  <joint name="A" type="fixed">
    <parent link="base_rm"/>
    <child link="coxa_rm"/>
    <origin xyz="2.632 0 0"/>
  </joint>
  <!-- DOF1 = q1 -->
  <joint name="joint1_rm" type="continuous">
    <parent link="coxa_rm"/>
    <child link="link1_rm"/>
    <origin rpy="0 0 0" xyz="0 0 0"/>
    <axis xyz="0 0 1"/>
    <dynamics damping="0.7"/>
  </joint>
  <!-- DOF2 = q2 -->
  <joint name="joint2_rm" type="continuous">
    <parent link="link1_rm"/>
    <child link="link2_rm"/>
    <origin rpy="-1.57079632679 0 0" xyz="0 0 0"/>
    <axis xyz="0 0 1"/>
    <dynamics damping="0.7"/>
  </joint>
  <!-- DOF3 = q3 -->
  <joint name="joint3_rm" type="continuous">
    <parent link="link2_rm"/>
    <child link="femur_rm"/>
    <origin rpy="1.57079632679 0 0" xyz="0 0 0"/>
    <axis xyz="0 0 1"/>
    <dynamics damping="0.7"/>
  </joint>
  <!-- DOF4 = q4 -->
  <joint name="joint4_rm" type="continuous">
    <parent link="femur_rm"/>
    <child link="tibia_rm"/>
    <origin rpy="0 0 0" xyz="1.7 0 0"/>
    <axis xyz="0 0 1"/>
    <dynamics damping="0.7"/>
  </joint>
  <gazebo reference="coxa_rm">
    <material>Gazebo/Blue</material>
  </gazebo>
  <gazebo reference="femur_rm">
    <material>Gazebo/Green</material>
  </gazebo>
  <gazebo reference="link1_rm">
    <material>Gazebo/Orange</material>
  </gazebo>
  <gazebo reference="link2_rm">
    <material>Gazebo/Red</material>
  </gazebo>
  <!-- Transmission to ROS -->
  <transmission name="tran1_rm">
    <type>transmission_interface/SimpleTransmission</type>
    <joint name="joint1_rm">
      <hardwareInterface>EffortJointInterface</hardwareInterface>
    </joint>
    <actuator name="motor1_rm">
      <hardwareInterface>EffortJointInterface</hardwareInterface>
      <mechanicalReduction>1</mechanicalReduction>
    </actuator>
  </transmission>
  <transmission name="tran2_rm">
    <type>transmission_interface/SimpleTransmission</type>
    <joint name="joint2_rm">
      <hardwareInterface>EffortJointInterface</hardwareInterface>
    </joint>
    <actuator name="motor2_rm">
      <hardwareInterface>EffortJointInterface</hardwareInterface>
      <mechanicalReduction>1</mechanicalReduction>
    </actuator>
  </transmission>
  <transmission name="tran3_rm">
    <type>transmission_interface/SimpleTransmission</type>
    <joint name="joint3_rm">
      <hardwareInterface>EffortJointInterface</hardwareInterface>
    </joint>
    <actuator name="motor3_rm">
      <hardwareInterface>EffortJointInterface</hardwareInterface>
      <mechanicalReduction>1</mechanicalReduction>
    </actuator>
  </transmission>
  <transmission name="tran4_rm">
    <type>transmission_interface/SimpleTransmission</type>
    <joint name="joint4_rm">
      <hardwareInterface>EffortJointInterface</hardwareInterface>
    </joint>
    <actuator name="motor4_rm">
      <hardwareInterface>EffortJointInterface</hardwareInterface>
      <mechanicalReduction>1</mechanicalReduction>
    </actuator>
  </transmission>
  <!-- Base -->
  <link name="base_rr">
    <collision>
      <origin rpy="0 0 0" xyz="0 0 -2.00635"/>
      <geometry>
        <box size="0.1 0.1 5"/>
      </geometry>
    </collision>
    <visual>
      <origin rpy="0 0 0" xyz="1.316 0 0"/>
      <geometry>
        <box size="2.632 0.1 0.1"/>
      </geometry>
      <material name="orange"/>
    </visual>
    <inertial>
      <origin rpy="0 0 0" xyz="0 0 2.5"/>
      <mass value="0.024357719"/>
      <inertia ixx="0.0507655460158" ixy="0.0" ixz="0.0" iyy="0.0507655460158" iyz="0.0" izz="4.05961983333e-05"/>
    </inertial>
  </link>
  <!-- Coxa Link -->
  <link name="coxa_rr">
    <collision>
      <origin rpy="0 0 0" xyz="0 0 0"/>
      <geometry>
        <box size="0.1 0.1 0.1"/>
      </geometry>
    </collision>
    <visual>
      <origin rpy="0 0 0" xyz="0 0 0"/>
      <geometry>
        <box size="0.1 0.1 0.1"/>
      </geometry>
      <material name="black"/>
    </visual>
    <inertial>
      <origin rpy="0 0 0" xyz="0 0 0"/>
      <mass value="0.024357719"/>
      <inertia ixx="0.0051411124" ixy="-0.00057530255" ixz="-0.000024729049" iyy="0.0081915737" iyz="-0.000019223094" izz="0.0011379812"/>
    </inertial>
  </link>
  <!-- Link DOF1 -->
  <link name="link1_rr">
    <collision>
      <origin rpy="0 0 0" xyz="0 0 0"/>
      <geometry>
        <box size="0.1 0.1 0.1"/>
      </geometry>
    </collision>
    <visual>
      <origin rpy="0 0 0" xyz="0 0 0"/>
      <geometry>
        <box size="0.1 0.1 0.1"/>
      </geometry>
      <material name="black"/>
    </visual>
    <inertial>
      <origin rpy="0 0 0" xyz="0 0 0"/>
      <mass value="0.024357719"/>
      <inertia ixx="0.0051411124" ixy="-0.00057530255" ixz="-0.000024729049" iyy="0.0081915737" iyz="-0.000019223094" izz="0.0011379812"/>
    </inertial>
  </link>
  <!-- Link DOF2 -->
  <link name="link2_rr">
    <collision>
      <origin rpy="0 0 0" xyz="0 0 0"/>
      <geometry>
        <box size="0.1 0.1 0.1"/>
      </geometry>
    </collision>
    <visual>
      <origin rpy="0 0 0" xyz="0 0 0"/>
      <geometry>
        <box size="0.1 0.1 0.1"/>
      </geometry>
      <material name="orange"/>
    </visual>
    <inertial>
      <origin rpy="0 0 0" xyz="0 0 0"/>
      <mass value="0.024357719"/>
      <inertia ixx="0.0051411124" ixy="-0.00057530255" ixz="-0.000024729049" iyy="0.0081915737" iyz="-0.000019223094" izz="0.0011379812"/>
    </inertial>
  </link>
  <!-- Femur Link -->
  <link name="femur_rr">
    <collision>
      <origin rpy="0 1.57079632679 0" xyz="0.85 0 0"/>
      <geometry>
        <cylinder length="1.7" radius="0.05"/>
      </geometry>
    </collision>
    <visual>
      <origin rpy="0 1.57079632679 0" xyz="0.85 0 0"/>
      <geometry>
        <cylinder length="1.7" radius="0.05"/>
      </geometry>
      <material name="orange"/>
    </visual>
    <inertial>
      <origin rpy="0 0 0" xyz="0.85 0 0"/>
      <mass value="0.024357719"/>
      <inertia ixx="0.0051411124" ixy="-0.00057530255" ixz="-0.000024729049" iyy="0.0081915737" iyz="-0.000019223094" izz="0.0011379812"/>
    </inertial>
  </link>
  <!-- Tibia Link -->
  <link name="tibia_rr">
    <collision>
      <origin rpy="0 1.57079632679 0" xyz="1.3 0 0"/>
      <geometry>
        <cylinder length="2.6" radius="0.02"/>
      </geometry>
    </collision>
    <visual>
      <origin rpy="0 1.57079632679 0" xyz="1.3 0 0"/>
      <geometry>
        <cylinder length="2.6" radius="0.02"/>
      </geometry>
      <material name="orange"/>
    </visual>
    <inertial>
      <origin rpy="0 0 0" xyz="1.3 0 0"/>
      <mass value="0.024357719"/>
      <inertia ixx="0.0051411124" ixy="-0.00057530255" ixz="-0.000024729049" iyy="0.0081915737" iyz="-0.000019223094" izz="0.0011379812"/>
    </inertial>
    <mu1>1</mu1>
    <mu2>1</mu2>
  </link>
  <joint name="j_body_rr" type="fixed">
    <parent link="body"/>
    <child link="base_rr"/>
    <origin rpy="0.61979265359 -0.1517 1.6559" xyz="-2.0 -0.35 2.00635"/>
  </joint>
  <!-- Frame {A} -->
  <joint name="A" type="fixed">
    <parent link="base_rr"/>
    <child link="coxa_rr"/>
    <origin xyz="2.632 0 0"/>
  </joint>
  <!-- DOF1 = q1 -->
  <joint name="joint1_rr" type="continuous">
    <parent link="coxa_rr"/>
    <child link="link1_rr"/>
    <origin rpy="0 0 0" xyz="0 0 0"/>
    <axis xyz="0 0 1"/>
    <dynamics damping="0.7"/>
  </joint>
  <!-- DOF2 = q2 -->
  <joint name="joint2_rr" type="continuous">
    <parent link="link1_rr"/>
    <child link="link2_rr"/>
    <origin rpy="-1.57079632679 0 0" xyz="0 0 0"/>
    <axis xyz="0 0 1"/>
    <dynamics damping="0.7"/>
  </joint>
  <!-- DOF3 = q3 -->
  <joint name="joint3_rr" type="continuous">
    <parent link="link2_rr"/>
    <child link="femur_rr"/>
    <origin rpy="1.57079632679 0 0" xyz="0 0 0"/>
    <axis xyz="0 0 1"/>
    <dynamics damping="0.7"/>
  </joint>
  <!-- DOF4 = q4 -->
  <joint name="joint4_rr" type="continuous">
    <parent link="femur_rr"/>
    <child link="tibia_rr"/>
    <origin rpy="0 0 0" xyz="1.7 0 0"/>
    <axis xyz="0 0 1"/>
    <dynamics damping="0.7"/>
  </joint>
  <gazebo reference="coxa_rr">
    <material>Gazebo/Blue</material>
  </gazebo>
  <gazebo reference="femur_rr">
    <material>Gazebo/Green</material>
  </gazebo>
  <gazebo reference="link1_rr">
    <material>Gazebo/Orange</material>
  </gazebo>
  <gazebo reference="link2_rr">
    <material>Gazebo/Red</material>
  </gazebo>
  <!-- Transmission to ROS -->
  <transmission name="tran1_rr">
    <type>transmission_interface/SimpleTransmission</type>
    <joint name="joint1_rr">
      <hardwareInterface>EffortJointInterface</hardwareInterface>
    </joint>
    <actuator name="motor1_rr">
      <hardwareInterface>EffortJointInterface</hardwareInterface>
      <mechanicalReduction>1</mechanicalReduction>
    </actuator>
  </transmission>
  <transmission name="tran2_rr">
    <type>transmission_interface/SimpleTransmission</type>
    <joint name="joint2_rr">
      <hardwareInterface>EffortJointInterface</hardwareInterface>
    </joint>
    <actuator name="motor2_rr">
      <hardwareInterface>EffortJointInterface</hardwareInterface>
      <mechanicalReduction>1</mechanicalReduction>
    </actuator>
  </transmission>
  <transmission name="tran3_rr">
    <type>transmission_interface/SimpleTransmission</type>
    <joint name="joint3_rr">
      <hardwareInterface>EffortJointInterface</hardwareInterface>
    </joint>
    <actuator name="motor3_rr">
      <hardwareInterface>EffortJointInterface</hardwareInterface>
      <mechanicalReduction>1</mechanicalReduction>
    </actuator>
  </transmission>
  <transmission name="tran4_rr">
    <type>transmission_interface/SimpleTransmission</type>
    <joint name="joint4_rr">
      <hardwareInterface>EffortJointInterface</hardwareInterface>
    </joint>
    <actuator name="motor4_rr">
      <hardwareInterface>EffortJointInterface</hardwareInterface>
      <mechanicalReduction>1</mechanicalReduction>
    </actuator>
  </transmission>
</robot>

